Workbook

Sheet Zalozenia
A1: ValenOS - model finansowy
A2: Komorki niebieskie to dane wejsciowe. Zmien je, a caly model przeliczy sie sam. Komorki czarne to formuly - nie nadpisuj.
A3: Kurs PLN/USD | B3: 3.85 | D3: Zalozenie
A5: Koszt tokenow na jednostke (USD)
A6: Screening jednej firmy | B6: 0.03 | D6: Zalozenie. Model tani, krotki prompt.
A7: Wzbogacenie jednej firmy | B7: 0.15 | D7: Zalozenie. Przy zoptymalizowanej ekstrakcji tresci. Bez niej ok. 0,60.
A8: Wzbogacenie jednego kontaktu | B8: 0.025 | D8: Zalozenie
A9: Napisanie i wyslanie maila | B9: 0.02 | D9: Zalozenie. Przy cache'owaniu kontekstu.
A10: Jedna akcja agenta CRM | B10: 0.005 | D10: Zalozenie
A12: Wolumen na jednego klienta miesiecznie
A13: Firmy przeskanowane | B13: 1000 | D13: Zalozenie - DO POTWIERDZENIA
A14: Firmy wzbogacone | B14: 250 | D14: Zalozenie - DO POTWIERDZENIA
A15: Kontakty wzbogacone | B15: 600 | D15: Zalozenie - DO POTWIERDZENIA
A16: Maile wyslane | B16: 2400 | D16: Zalozenie. Ok. 110 dziennie - sufit dostarczalnosci.
A17: Akcje agenta CRM | B17: 2000 | D17: Zalozenie
A19: Pozostale koszty obslugi (PLN/mies.)
A20: Dane przy 1 kliencie | B20: 240 | D20: Apollo, wyszukiwarka, weryfikacja, wysylka. Klient wysyla z wlasnych domen.
A21: Dane przy 10 klientach | B21: 230
A22: Dane przy 50 klientach | B22: 215
A23: Infrastruktura lacznie przy 1 | B23: 770 | D23: Hosting, baza, workery, auth, monitoring
A24: Infrastruktura lacznie przy 10 | B24: 1230
A25: Infrastruktura lacznie przy 50 | B25: 3465
A26: Wsparcie przy 1 | B26: 300 | D26: 3 h/mies. po 100 PLN - koszt alternatywny czasu
A27: Wsparcie przy 10 | B27: 250
A28: Wsparcie przy 50 | B28: 200
A30: Cennik
A31: Abonament founding (PLN/mies.) | B31: 3000 | D31: Zablokowany na stale - patrz zakladka Kohorta
A32: Abonament standard (PLN/mies.) | B32: 5000
A33: Oplata wdrozeniowa (standard) | B33: 6000
A35: Koszty stale (PLN/mies., bez wynagrodzen)
A36: Wlasny stack outboundowy | B36: 2000
A37: Infrastruktura bazowa | B37: 770
A38: Ksiegowosc | B38: 600
A39: Narzedzia zalozycieli | B39: 400
A40: Bank, domeny, pozostale | B40: 150
A41: Razem koszty stale | B41: =SUM(B36:B40)
A42: ZUS jedynego wspolnika (jesli dotyczy) | B42: 0 | D42: Wpisz 1900 jesli spolka jest jednoosobowa
A44: Wynagrodzenia
A45: Pensja brutto jednego zalozyciela | B45: 10000
A46: Narzut pracodawcy | B46: 1.2048 | D46: ZUS po stronie pracodawcy ok. 20,5%
...

Sheet Koszt obslugi
A1: Koszt obslugi: gotowka a koszt pelny
A3: Skladnik | B3: 1 klient | C3: 10 klientow | D3: 50 klientow
A4: Inferencja modelowa | B4: =('Zalozenia'!$B$6*'Zalozenia'!$B$13+'Zalozenia'!$B$7*'Zalozenia'!$B$14+'Zalozenia'!$B$8*'Zalozenia'!$B$15+'Zalozenia'!$B$9*'Zalozenia'!$B$16+'Zalozenia'!$B$10*'Zalozenia'!$B$17)*'Zalozenia'!$B$3 | C4: =('Zalozenia'!$B$6*'Zalozenia'!$B$13+'Zalozenia'!$B$7*'Zalozenia'!$B$14+'Zalozenia'!$B$8*'Zalozenia'!$B$15+'Zalozenia'!$B$9*'Zalozenia'!$B$16+'Zalozenia'!$B$10*'Zalozenia'!$B$17)*'Zalozenia'!$B$3 | D4: =('Zalozenia'!$B$6*'Zalozenia'!$B$13+'Zalozenia'!$B$7*'Zalozenia'!$B$14+'Zalozenia'!$B$8*'Zalozenia'!$B$15+'Zalozenia'!$B$9*'Zalozenia'!$B$16+'Zalozenia'!$B$10*'Zalozenia'!$B$17)*'Zalozenia'!$B$3
A5: Dane: Apollo, wyszukiwarka, weryfikacja | B5: ='Zalozenia'!$B$20 | C5: ='Zalozenia'!$B$21 | D5: ='Zalozenia'!$B$22
A6: Infrastruktura przypadajaca na klienta | B6: ='Zalozenia'!$B$23/1 | C6: ='Zalozenia'!$B$24/10 | D6: ='Zalozenia'!$B$25/50
A7: Wsparcie | B7: ='Zalozenia'!$B$26 | C7: ='Zalozenia'!$B$27 | D7: ='Zalozenia'!$B$28
A8: Razem | B8: =SUM(B4:B7) | C8: =SUM(C4:C7) | D8: =SUM(D4:D7)
A10: UWAGA: wiersz Razem to koszt PELNY, czyli z infrastruktura platformy podzielona przez liczbe klientow i z wycenionym czasem zalozycieli.
A11: Gotowka wychodzaca to tylko inferencja plus dane. Przy jednym kliencie infrastruktura to cala platforma, a nie koszt tego klienta. Patrz zakladka Model cenowy.
A12: Koszt krancowy gotowkowy na klienta (sredni wolumen) | B12: =B4+B5

Sheet Cennik
A1: Cennik: retainer z limitem stanowisk i pakietem wolumenu
A2: Niebieskie komorki to dane wejsciowe. Pakiety wolumenu ustaw na podstawie pomiaru na czterech firmach testujacych.
A4: Pozycja | B4: Start | C4: Standard | D4: Skala
A5: Stanowiska w cenie | B5: 3 | C5: 10 | D5: 25
A6: Firmy przeskanowane / mies. | B6: 200 | C6: 800 | D6: 2400
A7: Firmy wzbogacone / mies. | B7: 50 | C7: 200 | D7: 600
A8: Kontakty wzbogacone / mies. | B8: 150 | C8: 500 | D8: 1500
A9: Maile / mies. | B9: 500 | C9: 2000 | D9: 6000
A10: Akcje agenta CRM / mies. | B10: 500 | C10: 2000 | D10: 5000
A11: Dane na klienta (PLN/mies.) | B11: 60 | C11: 180 | D11: 450
A13: Cena (PLN/mies.) | B13: 990 | C13: 2490 | D13: 5900
A15: Inferencja | B15: =('Zalozenia'!$B$6*B6+'Zalozenia'!$B$7*B7+'Zalozenia'!$B$8*B8+'Zalozenia'!$B$9*B9+'Zalozenia'!$B$10*B10)*'Zalozenia'!$B$3 | C15: =('Zalozenia'!$B$6*C6+'Zalozenia'!$B$7*C7+'Zalozenia'!$B$8*C8+'Zalozenia'!$B$9*C9+'Zalozenia'!$B$10*C10)*'Zalozenia'!$B$3 | D15: =('Zalozenia'!$B$6*D6+'Zalozenia'!$B$7*D7+'Zalozenia'!$B$8*D8+'Zalozenia'!$B$9*D9+'Zalozenia'!$B$10*D10)*'Zalozenia'!$B$3
A16: Dane | B16: =B11 | C16: =C11 | D16: =D11
A17: Koszt krancowy gotowkowy | B17: =B15+B16 | C17: =C15+C16 | D17: =D15+D16
A18: Zysk brutto | B18: =B13-B17 | C18: =C13-C17 | D18: =D13-D17
A19: Marza brutto | B19: =B18/B13 | C19: =C18/C13 | D19: =D18/D13
A21: Mieszanka klientow
A22: Plan | B22: Udzial | C22: Cena | D22: Koszt
A23: Start | B23: 0.2 | C23: =B13 | D23: =B17
A24: Standard | B24: 0.65 | C24: =C13 | D24: =C17
A25: Skala | B25: 0.15 | C25: =D13 | D25: =D17
A26: Srednia wazona cena | B26: =SUMPRODUCT(B23:B25,C23:C25)
A27: Sredni wazony koszt | B27: =SUMPRODUCT(B23:B25,D23:D25)
A28: Sredni zysk brutto | B28: =B26-B27
A29: Srednia marza | B29: =B28/B26
A31: Bez oplaty wdrozeniowej. Caly przychod jest powtarzalny.

Sheet Marza CAC LTV
A1: Marza brutto
A3: Cena | B3: 1 klient | C3: 10 klientow | D3: 50 klientow
A4: Zysk brutto przy cenie founding | B4: ='Zalozenia'!$B$31-'Koszt obslugi'!B8 | C4: ='Zalozenia'!$B$31-'Koszt obslugi'!C8 | D4: ='Zalozenia'!$B$31-'Koszt obslugi'!D8
A5: Marza przy cenie founding | B5: =('Zalozenia'!$B$31-'Koszt obslugi'!B8)/'Zalozenia'!$B$31 | C5: =('Zalozenia'!$B$31-'Koszt obslugi'!C8)/'Zalozenia'!$B$31 | D5: =('Zalozenia'!$B$31-'Koszt obslugi'!D8)/'Zalozenia'!$B$31
A6: Zysk brutto przy cenie standard | B6: ='Zalozenia'!$B$32-'Koszt obslugi'!B8 | C6: ='Zalozenia'!$B$32-'Koszt obslugi'!C8 | D6: ='Zalozenia'!$B$32-'Koszt obslugi'!D8
A7: Marza przy cenie standard | B7: =('Zalozenia'!$B$32-'Koszt obslugi'!B8)/'Zalozenia'!$B$32 | C7: =('Zalozenia'!$B$32-'Koszt obslugi'!C8)/'Zalozenia'!$B$32 | D7: =('Zalozenia'!$B$32-'Koszt obslugi'!D8)/'Zalozenia'!$B$32
A9: Koszt pozyskania klienta (CAC)
A11: Konwersja ze spotkania | B11: Zamkniec/mies. | C11: CAC tylko narzedzia | D11: CAC z czasem zalozyciela
A12: 0.05 | B12: ='Zalozenia'!$B$51*A12 | C12: ='Zalozenia'!$B$52/B12 | D12: =('Zalozenia'!$B$52+'Zalozenia'!$B$53)/B12
A13: 0.08 | B13: ='Zalozenia'!$B$51*A13 | C13: ='Zalozenia'!$B$52/B13 | D13: =('Zalozenia'!$B$52+'Zalozenia'!$B$53)/B13
A14: 0.1 | B14: ='Zalozenia'!$B$51*A14 | C14: ='Zalozenia'!$B$52/B14 | D14: =('Zalozenia'!$B$52+'Zalozenia'!$B$53)/B14
A15: 0.15 | B15: ='Zalozenia'!$B$51*A15 | C15: ='Zalozenia'!$B$52/B15 | D15: =('Zalozenia'!$B$52+'Zalozenia'!$B$53)/B15
A17: Konwersja ze spotkania jest ZALOZENIEM. 26 spotkan sprzedawalo usluge, nie ValenOS w cenie 5 000 PLN.
A19: LTV i zwrot (klient standard)
A21: Pozycja | B21: Wartosc
A22: Zysk brutto miesiecznie (10 klientow) | B22: =C6
A23: Churn miesieczny | B23: ='Zalozenia'!$B$69
A24: Srednia dlugosc zycia klienta (mies.) | B24: =1/B23
A25: Zysk z oplaty wdrozeniowej | B25: ='Zalozenia'!$B$33-1200
A26: LTV | B26: =B22*B24+B25
A27: CAC (konwersja 8%, z czasem zalozyciela) | B27: =D13
A28: LTV / CAC | B28: =B26/B27
A29: Zwrot CAC z samej oplaty wdrozeniowej (mies.) | B29: =B27/(B22+B25)
A31: Nie podawaj LTV/CAC inwestorowi. Obie dane wejsciowe sa niezmierzone, a iloraz eksploduje. Mocniejsze zdanie: oplata wdrozeniowa pokrywa CAC w pierwszym tygodniu.

Sheet Prog rentownosci
A1: Prog rentownosci
A3: Koszty stale miesiecznie (z ZUS jedynego wspolnika) | B3: ='Zalozenia'!$B$41+'Zalozenia'!$B$42
A5: Scenariusz | B5: Koszt do pokrycia | C5: Zysk brutto na kliencie | D5: Potrzebni klienci
A6: Bez wynagrodzen | B6: =B3 | C6: =Cennik!$B$28 | D6: =ROUNDUP(B6/C6,0)
A7: Pensja dla Bruna | B7: =B3+'Zalozenia'!$B$47 | C7: =Cennik!$B$28 | D7: =ROUNDUP(B7/C7,0)
A8: Pensje dla obu zalozycieli | B8: =B3+'Zalozenia'!$B$48 | C8: =Cennik!$B$28 | D8: =ROUNDUP(B8/C8,0)
A11: Sufit przepustowosci, model masowy
A12: Godziny Mario przy 50 klientach | B12: =40+'Zalozenia'!$B$51*1.5+5*'Zalozenia'!$B$97+50*'Zalozenia'!$B$98
A13: Godziny Mario przy 100 klientach | B13: =40+'Zalozenia'!$B$51*1.5+5*'Zalozenia'!$B$97+100*'Zalozenia'!$B$98
A14: W modelu bespoke sufit wypadal okolo 20 klientow.

Sheet Kohorta founding
A1: Koszt kohorty founding members
A3: Utracony abonament miesiecznie na osobe | B3: ='Zalozenia'!$B$32-'Zalozenia'!$B$31
A4: Utracona oplata wdrozeniowa na osobe | B4: ='Zalozenia'!$B$33
A5: Koszt jednej osoby przez 3 lata | B5: =B3*36+B4
A7: Wielkosc kohorty | B7: Miesiecznie | C7: Rocznie | D7: Przez 3 lata
A8: 3 | B8: =A8*$B$3 | C8: =A8*$B$3*12 | D8: =A8*$B$5
A9: 4 | B9: =A9*$B$3 | C9: =A9*$B$3*12 | D9: =A9*$B$5
A10: 6 | B10: =A10*$B$3 | C10: =A10*$B$3*12 | D10: =A10*$B$5
A11: 10 | B11: =A11*$B$3 | C11: =A11*$B$3*12 | D11: =A11*$B$5
A13: Argument inwestycyjny: runda kupuje prawo do nierozdawania rabatow
A14: Kohorta bez rundy (zalozenie) | B14: 6
A15: Kohorta z runda (decyzja) | B15: 3
A16: Osob bez rabatu | B16: =B14-B15
A17: Zachowany przychod przez 3 lata | B17: =B16*B5
A18: Jako wielokrotnosc rundy | B18: =B17/'Wykorzystanie srodkow'!B12
A20: Rekomendacja: zamknij kohorte na 3 lub 4 i ogranicz "na stale" do zakresu z dnia startu. Przy 10 osobach 3 000 PLN staje sie cena rynkowa, a nie rabatem.

Sheet Wykorzystanie srodkow
A1: Wykorzystanie srodkow z rundy (liczby od Mario)
A2: Okres: szesc miesiecy. Zalozyciele nie pobieraja wynagrodzenia z rundy.
A4: Claude Max 20x: liczba subskrypcji | B4: 4
A5: Claude Max 20x: cena miesieczna (USD) | B5: 200
A6: Okres (miesiecy) | B6: 6
A8: Pozycja | B8: Kwota | C8: Udzial | D8: Budowa?
A9: Claude Max 20x, cztery subskrypcje, szesc miesiecy | B9: =B4*B5*B6*'Zalozenia'!$B$3 | C9: =B9/$B$15 | D9: tak
A10: Narzedzia i API: Apollo, wyszukiwarka, wysylka, hosting | B10: 15000 | C10: =B10/$B$15 | D10: tak
A11: Marketing | B11: 10000 | C11: =B11/$B$15 | D11: nie
A12: Ksiegowosc i operacje | B12: 5000 | C12: =B12/$B$15 | D12: nie
A13: Rezerwa | B13: =50000-SUM(B9:B12) | C13: =B13/$B$15 | D13: nie
A15: Razem | B15: =SUM(B9:B13) | C15: =SUM(C9:C13)
A17: Udzial na budowe produktu | B17: =SUMIF(D9:D13,"tak",B9:B13) | C17: =B17/B15
A19: Subskrypcje Claude Max pokrywaja prace zespolu nad produktem. Inferencja agentow u klientow to osobny koszt rozliczany per token, ktory jest kosztem przychodu i pokrywa go przychod, a nie runda.

Sheet Model cenowy
A1: Model cenowy: co naprawde kosztuje obsluga klienta
A2: Tylko gotowka wychodzaca. Infrastruktura platformy i czas zalozycieli NIE sa kosztem na klienta.
A4: Skladnik | B4: Niski wolumen | C4: Sredni wolumen | D4: Wysoki wolumen
A5: Inferencja modelowa | B5: =('Zalozenia'!$B$6*'Zalozenia'!$B$73+'Zalozenia'!$B$7*'Zalozenia'!$B$74+'Zalozenia'!$B$8*'Zalozenia'!$B$75+'Zalozenia'!$B$9*'Zalozenia'!$B$76+'Zalozenia'!$B$10*'Zalozenia'!$B$77)*'Zalozenia'!$B$3 | C5: =('Zalozenia'!$B$6*'Zalozenia'!$C$73+'Zalozenia'!$B$7*'Zalozenia'!$C$74+'Zalozenia'!$B$8*'Zalozenia'!$C$75+'Zalozenia'!$B$9*'Zalozenia'!$C$76+'Zalozenia'!$B$10*'Zalozenia'!$C$77)*'Zalozenia'!$B$3 | D5: =('Zalozenia'!$B$6*'Zalozenia'!$D$73+'Zalozenia'!$B$7*'Zalozenia'!$D$74+'Zalozenia'!$B$8*'Zalozenia'!$D$75+'Zalozenia'!$B$9*'Zalozenia'!$D$76+'Zalozenia'!$B$10*'Zalozenia'!$D$77)*'Zalozenia'!$B$3
A6: Dane: Apollo, wyszukiwarka, weryfikacja | B6: ='Zalozenia'!$B$78 | C6: ='Zalozenia'!$C$78 | D6: ='Zalozenia'!$D$78
A7: Koszt krancowy gotowkowy na klienta | B7: =B5+B6 | C7: =C5+C6 | D7: =D5+D6
A9: Rozpietosc miedzy najlzejszym a najciezszym klientem | B9: =D7/B7
A10: Limit stanowisk NIE ogranicza tej rozpietosci. Ten sam klient moze miec 3 stanowiska przy kazdym z tych wolumenow.
A12: Koszt krancowy jako udzial ceny
A14: Cena abonamentu | B14: Niski | C14: Sredni | D14: Wysoki
A15: ='Zalozenia'!$B$31 | B15: =B$7/$A15 | C15: =C$7/$A15 | D15: =D$7/$A15
A16: ='Zalozenia'!$B$32 | B16: =B$7/$A16 | C16: =C$7/$A16 | D16: =D$7/$A16
A18: Rama porownawcza dla kupujacego (PLN/mies., szacunki rynkowe)
A20: Alternatywa klienta | B20: Od | C20: Do
A21: Junior SDR, pelny koszt pracodawcy | B21: 8500 | C21: 11000
A22: Agencja outboundowa, retainer | B22: 5000 | C22: 15000
A23: CRM rozliczany per stanowisko, 5 stanowisk | B23: 245 | C23: 1250
A25: ValenOS przy cenie standard | B25: ='Zalozenia'!$B$32
A26: Przy wycenie per stanowisko, 5 stanowisk, wyszloby na stanowisko | B26: ='Zalozenia'!$B$32/5
A27: Gorna granica polskiego rynku CRM za stanowisko | B27: 250
A28: Ile razy powyzej rynku | B28: =B26/B27
A30: Wniosek: retainer ustawia porownanie z kosztem handlowca lub agencji, gdzie ValenOS wygrywa. Wycena per stanowisko ustawia porownanie z Pipedrive, gdzie przegrywa 4x.

Sheet Plan 12 miesiecy
A1: Plan dwunastu miesiecy, model masowy
A2: PROGNOZA. Brak oplaty wdrozeniowej, caly przychod powtarzalny.
A4: Mies. | B4: Konwersja | C4: Nowych | D4: Klientow | E4: MRR | F4: COGS | G4: Koszty stale | H4: Wynik | I4: Narastajaco | J4: Godziny Mario
A5: 1 | B5: =IF(A5<=3,'Zalozenia'!$B$93,IF(A5<=6,'Zalozenia'!$B$94,IF(A5<=9,'Zalozenia'!$B$95,'Zalozenia'!$B$96))) | C5: ='Zalozenia'!$B$51*B5 | D5: =C5 | E5: =D5*Cennik!$B$26 | F5: =D5*Cennik!$B$27 | G5: ='Zalozenia'!$B$41+'Zalozenia'!$B$42 | H5: =E5-F5-G5 | I5: =H5 | J5: =40+'Zalozenia'!$B$51*1.5+C5*'Zalozenia'!$B$97+D5*'Zalozenia'!$B$98
A6: 2 | B6: =IF(A6<=3,'Zalozenia'!$B$93,IF(A6<=6,'Zalozenia'!$B$94,IF(A6<=9,'Zalozenia'!$B$95,'Zalozenia'!$B$96))) | C6: ='Zalozenia'!$B$51*B6 | D6: =D5*(1-'Zalozenia'!$B$62)+C6 | E6: =D6*Cennik!$B$26 | F6: =D6*Cennik!$B$27 | G6: ='Zalozenia'!$B$41+'Zalozenia'!$B$42 | H6: =E6-F6-G6 | I6: =I5+H6 | J6: =40+'Zalozenia'!$B$51*1.5+C6*'Zalozenia'!$B$97+D6*'Zalozenia'!$B$98
A7: 3 | B7: =IF(A7<=3,'Zalozenia'!$B$93,IF(A7<=6,'Zalozenia'!$B$94,IF(A7<=9,'Zalozenia'!$B$95,'Zalozenia'!$B$96))) | C7: ='Zalozenia'!$B$51*B7 | D7: =D6*(1-'Zalozenia'!$B$62)+C7 | E7: =D7*Cennik!$B$26 | F7: =D7*Cennik!$B$27 | G7: ='Zalozenia'!$B$41+'Zalozenia'!$B$42 | H7: =E7-F7-G7 | I7: =I6+H7 | J7: =40+'Zalozenia'!$B$51*1.5+C7*'Zalozenia'!$B$97+D7*'Zalozenia'!$B$98
A8: 4 | B8: =IF(A8<=3,'Zalozenia'!$B$93,IF(A8<=6,'Zalozenia'!$B$94,IF(A8<=9,'Zalozenia'!$B$95,'Zalozenia'!$B$96))) | C8: ='Zalozenia'!$B$51*B8 | D8: =D7*(1-'Zalozenia'!$B$62)+C8 | E8: =D8*Cennik!$B$26 | F8: =D8*Cennik!$B$27 | G8: ='Zalozenia'!$B$41+'Zalozenia'!$B$42 | H8: =E8-F8-G8 | I8: =I7+H8 | J8: =40+'Zalozenia'!$B$51*1.5+C8*'Zalozenia'!$B$97+D8*'Zalozenia'!$B$98
A9: 5 | B9: =IF(A9<=3,'Zalozenia'!$B$93,IF(A9<=6,'Zalozenia'!$B$94,IF(A9<=9,'Zalozenia'!$B$95,'Zalozenia'!$B$96))) | C9: ='Zalozenia'!$B$51*B9 | D9: =D8*(1-'Zalozenia'!$B$62)+C9 | E9: =D9*Cennik!$B$26 | F9: =D9*Cennik!$B$27 | G9: ='Zalozenia'!$B$41+'Zalozenia'!$B$42 | H9: =E9-F9-G9 | I9: =I8+H9 | J9: =40+'Zalozenia'!$B$51*1.5+C9*'Zalozenia'!$B$97+D9*'Zalozenia'!$B$98
A10: 6 | B10: =IF(A10<=3,'Zalozenia'!$B$93,IF(A10<=6,'Zalozenia'!$B$94,IF(A10<=9,'Zalozenia'!$B$95,'Zalozenia'!$B$96))) | C10: ='Zalozenia'!$B$51*B10 | D10: =D9*(1-'Zalozenia'!$B$62)+C10 | E10: =D10*Cennik!$B$26 | F10: =D10*Cennik!$B$27 | G10: ='Zalozenia'!$B$41+'Zalozenia'!$B$42 | H10: =E10-F10-G10 | I10: =I9+H10 | J10: =40+'Zalozenia'!$B$51*1.5+C10*'Zalozenia'!$B$97+D10*'Zalozenia'!$B$98
A11: 7 | B11: =IF(A11<=3,'Zalozenia'!$B$93,IF(A11<=6,'Zalozenia'!$B$94,IF(A11<=9,'Zalozenia'!$B$95,'Zalozenia'!$B$96))) | C11: ='Zalozenia'!$B$51*B11 | D11: =D10*(1-'Zalozenia'!$B$62)+C11 | E11: =D11*Cennik!$B$26 | F11: =D11*Cennik!$B$27 | G11: ='Zalozenia'!$B$41+'Zalozenia'!$B$42 | H11: =E11-F11-G11 | I11: =I10+H11 | J11: =40+'Zalozenia'!$B$51*1.5+C11*'Zalozenia'!$B$97+D11*'Zalozenia'!$B$98
A12: 8 | B12: =IF(A12<=3,'Zalozenia'!$B$93,IF(A12<=6,'Zalozenia'!$B$94,IF(A12<=9,'Zalozenia'!$B$95,'Zalozenia'!$B$96))) | C12: ='Zalozenia'!$B$51*B12 | D12: =D11*(1-'Zalozenia'!$B$62)+C12 | E12: =D12*Cennik!$B$26 | F12: =D12*Cennik!$B$27 | G12: ='Zalozenia'!$B$41+'Zalozenia'!$B$42 | H12: =E12-F12-G12 | I12: =I11+H12 | J12: =40+'Zalozenia'!$B$51*1.5+C12*'Zalozenia'!$B$97+D12*'Zalozenia'!$B$98
A13: 9 | B13: =IF(A13<=3,'Zalozenia'!$B$93,IF(A13<=6,'Zalozenia'!$B$94,IF(A13<=9,'Zalozenia'!$B$95,'Zalozenia'!$B$96))) | C13: ='Zalozenia'!$B$51*B13 | D13: =D12*(1-'Zalozenia'!$B$62)+C13 | E13: =D13*Cennik!$B$26 | F13: =D13*Cennik!$B$27 | G13: ='Zalozenia'!$B$41+'Zalozenia'!$B$42 | H13: =E13-F13-G13 | I13: =I12+H13 | J13: =40+'Zalozenia'!$B$51*1.5+C13*'Zalozenia'!$B$97+D13*'Zalozenia'!$B$98
A14: 10 | B14: =IF(A14<=3,'Zalozenia'!$B$93,IF(A14<=6,'Zalozenia'!$B$94,IF(A14<=9,'Zalozenia'!$B$95,'Zalozenia'!$B$96))) | C14: ='Zalozenia'!$B$51*B14 | D14: =D13*(1-'Zalozenia'!$B$62)+C14 | E14: =D14*Cennik!$B$26 | F14: =D14*Cennik!$B$27 | G14: ='Zalozenia'!$B$41+'Zalozenia'!$B$42 | H14: =E14-F14-G14 | I14: =I13+H14 | J14: =40+'Zalozenia'!$B$51*1.5+C14*'Zalozenia'!$B$97+D14*'Zalozenia'!$B$98
A15: 11 | B15: =IF(A15<=3,'Zalozenia'!$B$93,IF(A15<=6,'Zalozenia'!$B$94,IF(A15<=9,'Zalozenia'!$B$95,'Zalozenia'!$B$96))) | C15: ='Zalozenia'!$B$51*B15 | D15: =D14*(1-'Zalozenia'!$B$62)+C15 | E15: =D15*Cennik!$B$26 | F15: =D15*Cennik!$B$27 | G15: ='Zalozenia'!$B$41+'Zalozenia'!$B$42 | H15: =E15-F15-G15 | I15: =I14+H15 | J15: =40+'Zalozenia'!$B$51*1.5+C15*'Zalozenia'!$B$97+D15*'Zalozenia'!$B$98
A16: 12 | B16: =IF(A16<=3,'Zalozenia'!$B$93,IF(A16<=6,'Zalozenia'!$B$94,IF(A16<=9,'Zalozenia'!$B$95,'Zalozenia'!$B$96))) | C16: ='Zalozenia'!$B$51*B16 | D16: =D15*(1-'Zalozenia'!$B$62)+C16 | E16: =D16*Cennik!$B$26 | F16: =D16*Cennik!$B$27 | G16: ='Zalozenia'!$B$41+'Zalozenia'!$B$42 | H16: =E16-F16-G16 | I16: =I15+H16 | J16: =40+'Zalozenia'!$B$51*1.5+C16*'Zalozenia'!$B$97+D16*'Zalozenia'!$B$98
A18: Wynik narastajaco po wycenie pracy obu zalozycieli | D18: =I16-'Zalozenia'!$B$48*12
A19: Kolumna Godziny Mario: outbound 40 h + spotkania + onboarding + wsparcie. Powyzej ~170 h potrzebna pierwsza osoba.
